<?xml version="1.0" ?>
<robot xmlns:xacro="http://ros.org/wiki/xacro">

<xacro:macro name="prarob_manipulator" params="parent *origin">
  <joint name="origin_to_link1" type="fixed">
    <xacro:insert_block name="origin" />
    <parent link="${parent}" />
    <child link="link1" />
    <origin xyz="0.0 0.0 0.0" rpy="0 0 0"/>
    <axis xyz="0 0 1" />
  </joint>

<xacro:include filename="$(find ros2_prarob)/urdf/materials.xacro" />
<!-- xacro:include filename="$(find ros2_prarob)/urdf/prarob_manipulator.trans" / -->
<!-- xacro:include filename="$(find ros2_prarob)/urdf/prarob_manipulator.gazebo" / -->

<link name="link1">
  <visual>
    <origin xyz="0 0 0" rpy="0 0 0"/>
    <geometry>
      <mesh filename="package://ros2_prarob/meshes/Postolje.stl" scale="0.001 0.001 0.001"/>
    </geometry>
    <material name="Steel"/>
  </visual>
  <collision>
    <origin xyz="0 0 0" rpy="0 0 0"/>
    <geometry>
      <mesh filename="package://ros2_prarob/meshes/Postolje.stl" scale="0.001 0.001 0.001"/>
    </geometry>
  </collision>
</link>

<link name="XL-430-DUMMY_1">
  <visual>
    <origin xyz="0 0 0" rpy="0 0 0"/>
    <geometry>
      <mesh filename="package://ros2_prarob/meshes/XL-430-DUMMY.stl" scale="0.001 0.001 0.001"/>
    </geometry>
    <material name="Steel"/>
  </visual>
  <collision>
    <origin xyz="0 0 0" rpy="0 0 0"/>
    <geometry>
      <mesh filename="package://ros2_prarob/meshes/XL-430-DUMMY.stl" scale="0.001 0.001 0.001"/>
    </geometry>
  </collision>
</link>

<link name="link2">
  <visual>
    <origin xyz="-4.4408920985e-18 0.0000000000e+00 0.0000000000e+00" rpy="0.0 0.0 0.0"/>
    <geometry>
      <mesh filename="package://ros2_prarob/meshes/Link_90.stl" scale="0.001 0.001 0.001"/>
    </geometry>
    <material name="Steel"/>
  </visual>
  <collision>
    <origin xyz="-4.4408920985e-18 0.0000000000e+00 0.0000000000e+00" rpy="0.0 0.0 0.0"/>
    <geometry>
      <mesh filename="package://ros2_prarob/meshes/Link_90.stl" scale="0.001 0.001 0.001"/>
    </geometry>
  </collision>
</link>

<link name="XL-430-DUMMY_2">
  <visual>
    <origin xyz="0.0 0.0 0.0" rpy="0.0 0.0 0.0"/>
    <geometry>
      <mesh filename="package://ros2_prarob/meshes/XL-430-DUMMY.stl" scale="0.001 0.001 0.001"/>
    </geometry>
    <material name="Steel"/>
  </visual>
  <collision>
    <origin xyz="0.0 0.0 0.0" rpy="0.0 0.0 0.0"/>
    <geometry>
      <mesh filename="package://ros2_prarob/meshes/XL-430-DUMMY.stl" scale="0.001 0.001 0.001"/>
    </geometry>
  </collision>
</link>

<link name="link3">
  <visual>
     <origin xyz="-1.0000000149e-01 0.0000000000e+00 -4.1000000000e-03" rpy="0.0 0.0 0.0"/>
    <geometry>
      <mesh filename="package://ros2_prarob/meshes/Link_RR.stl" scale="0.001 0.001 0.001"/>
    </geometry>
    <material name="Steel"/>
  </visual>
  <collision>
     <origin xyz="-1.0000000149e-01 0.0000000000e+00 -4.1000000000e-03" rpy="0.0 0.0 0.0"/>
    <geometry>
      <mesh filename="package://ros2_prarob/meshes/Link_RR.stl" scale="0.001 0.001 0.001"/>
    </geometry>
  </collision>
</link>

<link name="XL-430-DUMMY_3">
  <visual>
    <origin xyz="0.0000000000e+00 -7.1054273576e-17 -2.0900000000e-02" rpy="0.0 0.0 0.0"/>
    <geometry>
      <mesh filename="package://ros2_prarob/meshes/XL-430-DUMMY.stl" scale="0.001 0.001 0.001"/>
    </geometry>
    <material name="Steel"/>
  </visual>
  <collision>
    <origin xyz="0.0000000000e+00 -7.1054273576e-17 -2.0900000000e-02" rpy="0.0 0.0 0.0"/>
    <geometry>
      <mesh filename="package://ros2_prarob/meshes/XL-430-DUMMY.stl" scale="0.001 0.001 0.001"/>
    </geometry>
  </collision>
</link>

<link name="link_tool">
  <visual>
    <origin xyz="0.0 0.0 0.0" rpy="0.0 0.0 0.0"/>
    <geometry>
      <mesh filename="package://ros2_prarob/meshes/Izvrsni_clan.stl" scale="0.001 0.001 0.001"/>
    </geometry>
    <material name="Steel"/>
  </visual>
  <collision>
    <origin xyz="0.0 0.0 0.0" rpy="0.0 0.0 0.0"/>
    <geometry>
      <mesh filename="package://ros2_prarob/meshes/Izvrsni_clan.stl" scale="0.001 0.001 0.001"/>
    </geometry>
  </collision>
</link>



<joint name="rigid1" type="fixed">
  <origin xyz="1.2000000000e-02 -2.2204460493e-17 2.0000000000e-02" rpy="0.0 0.0 -1.570796"/>
  <parent link="link1"/>
  <child link="XL-430-DUMMY_1"/>
</joint>

<joint name="rigid2" type="fixed">
  <origin xyz="3.3217872897e-15 -1.6391000557e-10 4.5000000194e-02" rpy="1.570796 -0.0 1.570796"/>
  <parent link="link2"/>
  <child link="XL-430-DUMMY_2"/>
</joint>

<joint name="rigid3" type="fixed">
  <origin xyz="-1.6391275004e-10 -3.7000000075e-02 -2.0900000000e-02" rpy="1.570796 -1.570796 0.0"/>
  <parent link="XL-430-DUMMY_3"/>
  <child link="link_tool"/>
</joint>


<joint name="joint1" type="revolute">
  <origin xyz="8.8817841970e-18 2.6645352591e-17 2.2000000000e-02" rpy="0.0 0.0 1.570796"/>
  <parent link="XL-430-DUMMY_1"/>
  <child link="link2"/>
  <axis xyz="0.0 0.0 1.0"/>
  <limit velocity="10.0" effort="1" lower="-2.82743338823" upper="2.82743338823" />
</joint>

<joint name="joint2" type="revolute">
  <origin xyz="4.4408920985e-18 -4.4408920985e-18 2.0900000000e-02" rpy="-3.141593 0.0 -1.570796"/>
  <parent link="XL-430-DUMMY_2"/>
  <child link="link3"/>
  <axis xyz="0.0 0.0 1.0"/>
  <limit velocity="10.0" effort="1" lower="-2.82743338823" upper="2.82743338823" />
</joint>

<joint name="joint3" type="revolute">
  <origin xyz="-2.0000000298e-01 6.2172489379e-17 -6.2172489379e-17" rpy="3.141593 0.0 0.0"/>
  <!-- origin xyz="-2.0000000298e-01 6.2172489379e-17 -6.2172489379e-17" rpy="3.141593 0.0 1.570796"/-->
  <parent link="link3"/>
  <child link="XL-430-DUMMY_3"/>
  <axis xyz="0.0 0.0 1.0"/>
  <limit velocity="10.0" effort="1" lower="-2.82743338823" upper="2.82743338823" />
</joint>

</xacro:macro>
</robot>
